####################
# Assignment 4
####################

Overall: 5/51
====================
Test Case: [function=multiply_factors_test_1]	[2/2]
	MF Test 1 ....
P(smoker) = 0.5 P(non-smoker) = 0.5
multiply_factors_test_1: 
passed.
====================
Test Case: [function=multiply_factors_test_2]	[0/2]
	MF Test 2 ....
multiply_factors_test_2: 
A runtime error occurred: 'Traceback (most recent call last):\n  File "/Users/JaglalLab/Desktop/A4/A4-Final/autograder/auto_grader/student_grader/assignment/A4_tests.py", line 346, in multiply_factors_test_2\n    factor = stu_solution.multiply_factors([F1, F2])\n  File "../students/luxiu/A4/bnetbase.py", line 330, in multiply_factors\n    new_factor.add_values(new)\n  File "../students/luxiu/A4/bnetbase.py", line 169, in add_values\n    index = index * v.domain_size() + v.value_index(t[0])\n  File "../students/luxiu/A4/bnetbase.py", line 67, in value_index\n    return self.dom.index(value)\nValueError: \'v\' is not in list\n'
====================
Test Case: [function=multiply_factors_test_3]	[0/2]
	MF Test 3 ....
A runtime error occurred: 'Traceback (most recent call last):\n  File "/Users/JaglalLab/Desktop/A4/A4-Final/autograder/auto_grader/student_grader/assignment/A4_tests.py", line 391, in multiply_factors_test_3\n    factor = stu_solution.multiply_factors([F1, F5])\n  File "../students/luxiu/A4/bnetbase.py", line 327, in multiply_factors\n    val_1 = fact_1.get_value([dom1[j]])\n  File "../students/luxiu/A4/bnetbase.py", line 226, in get_value\n    index = index * v.domain_size() + v.value_index(variable_values[0])\nIndexError: list index out of range\n'
multiply_factors_test_3: 
====================
Test Case: [function=norm_test_1]	[1/1]
	{'[0, 1, 2, 3, 4] when normalized to [0.0, 0.1, 0.2, 0.30000000000000004, 0.4] sum to 1.0', 'Normalization test 1 ....', 'passed.'}
====================
Test Case: [function=norm_test_2]	[1/1]
	{'[0, -1, -2, -3, -4] when normalized to [-0.0, 0.1, 0.2, 0.30000000000000004, 0.4] sum to 1.0', 'Normalization test 2 ....', 'passed.'}
====================
Test Case: [function=norm_test_3]	[0/1]
	ZeroDivisionError was raised: division by zero
Traceback (most recent call last):
  File "/Users/JaglalLab/Desktop/A4/A4-Final/autograder/auto_grader/student_grader/grade.py", line 54, in grade_assignment
    test_case_result = assignment.run(test_case)
  File "/Users/JaglalLab/Desktop/A4/A4-Final/autograder/auto_grader/student_grader/assignment/assignment.py", line 53, in run
    grade, details = test_case.execute(path_modules)    # Run test case and return TestCaseResult
  File "/Users/JaglalLab/Desktop/A4/A4-Final/autograder/auto_grader/student_grader/assignment/test_case.py", line 70, in execute
    value = self._function(assignment_module)
  File "/Users/JaglalLab/Desktop/A4/A4-Final/autograder/auto_grader/student_grader/utils/test_tools.py", line 10, in _wrapper
    return func(*args, **kwargs)
  File "/Users/JaglalLab/Desktop/A4/A4-Final/autograder/auto_grader/student_grader/assignment/A4_tests.py", line 57, in norm_test_3
    normalized_nums = stu_solution.normalize([i for i in range(4,-5,-1)])
  File "../students/luxiu/A4/bnetbase.py", line 355, in normalize
    factor = 1 / s
ZeroDivisionError: division by zero

====================
Test Case: [function=old_VE_tests]	[0/8]
	OVE Test 4 ....
A runtime error occurred: 'Traceback (most recent call last):\n  File "/Users/JaglalLab/Desktop/A4/A4-Final/autograder/auto_grader/student_grader/assignment/A4_tests.py", line 684, in old_VE_tests\n    if abs(probs[0] - 0.68) < 0.0001 and abs(probs[1] - 0.32) < 0.0001:\nTypeError: \'NoneType\' object is not subscriptable\n'
A runtime error occurred: 'Traceback (most recent call last):\n  File "/Users/JaglalLab/Desktop/A4/A4-Final/autograder/auto_grader/student_grader/assignment/A4_tests.py", line 785, in old_VE_tests\n    if abs(probs[0] - 0.04950000000000001) < .0001 and abs(probs[1] - 0.9505) < .0001:\nTypeError: \'NoneType\' object is not subscriptable\n'
OVE Test 3 ....
Test 8 ....
A runtime error occurred: 'Traceback (most recent call last):\n  File "/Users/JaglalLab/Desktop/A4/A4-Final/autograder/auto_grader/student_grader/assignment/A4_tests.py", line 664, in old_VE_tests\n    if probs[0] == 1 and probs[1] == 0:\nTypeError: \'NoneType\' object is not subscriptable\n'
OVE Test 2 ....
A runtime error occurred: 'Traceback (most recent call last):\n  File "/Users/JaglalLab/Desktop/A4/A4-Final/autograder/auto_grader/student_grader/assignment/A4_tests.py", line 727, in old_VE_tests\n    if probs1[0] == 0.5 and probs1[1] == 0.5 and probs2[0] == 0.5 and probs2[1] == 0.5:\nTypeError: \'NoneType\' object is not subscriptable\n'
old_VE_tests: 
OVE Test 7 ....
A runtime error occurred: 'Traceback (most recent call last):\n  File "/Users/JaglalLab/Desktop/A4/A4-Final/autograder/auto_grader/student_grader/assignment/A4_tests.py", line 801, in old_VE_tests\n    if abs(probs[0] - 0.1) < 0.0001 and abs(probs[1] - 0.9) < 0.0001:\nTypeError: \'NoneType\' object is not subscriptable\n'
OVE Test 1 ....
OVE Test 5 ....
OVE Test 6 ....
A runtime error occurred: 'Traceback (most recent call last):\n  File "/Users/JaglalLab/Desktop/A4/A4-Final/autograder/auto_grader/student_grader/assignment/A4_tests.py", line 748, in old_VE_tests\n    if probs3[0] == 0.0 and probs3[1] == 1.0 and probs4[0] == 0.0 and probs4[1] == 1.0:\nTypeError: \'NoneType\' object is not subscriptable\n'
A runtime error occurred: 'Traceback (most recent call last):\n  File "/Users/JaglalLab/Desktop/A4/A4-Final/autograder/auto_grader/student_grader/assignment/A4_tests.py", line 705, in old_VE_tests\n    if probs1[0] == 0.5 and probs1[1] == 0.5 and probs2[0] == 0.0 and probs2[1] == 1.0:\nTypeError: \'NoneType\' object is not subscriptable\n'
A runtime error occurred: 'Traceback (most recent call last):\n  File "/Users/JaglalLab/Desktop/A4/A4-Final/autograder/auto_grader/student_grader/assignment/A4_tests.py", line 768, in old_VE_tests\n    if abs(probs1[0] - 0.15265998457979954) < 0.0001 and abs(probs1[1] - 0.8473400154202004) < 0.0001 and abs(probs2[0] - 0.01336753983256819) < 0.0001 and abs(probs2[1] - 0.9866324601674318) < 0.0001:\nTypeError: \'NoneType\' object is not subscriptable\n'
====================
Test Case: [function=old_multiply_factors_tests]	[1/3]
	OMF Test 3 ....
P(e) = 0.1 P(-e) = 0.9
OMF Test 2 ....
A runtime error occurred: 'Traceback (most recent call last):\n  File "/Users/JaglalLab/Desktop/A4/A4-Final/autograder/auto_grader/student_grader/assignment/A4_tests.py", line 857, in old_multiply_factors_tests\n    factor = stu_solution.multiply_factors([FB, FE])\n  File "../students/luxiu/A4/bnetbase.py", line 330, in multiply_factors\n    new_factor.add_values(new)\n  File "../students/luxiu/A4/bnetbase.py", line 169, in add_values\n    index = index * v.domain_size() + v.value_index(t[0])\nIndexError: string index out of range\n'
A runtime error occurred: 'Traceback (most recent call last):\n  File "/Users/JaglalLab/Desktop/A4/A4-Final/autograder/auto_grader/student_grader/assignment/A4_tests.py", line 884, in old_multiply_factors_tests\n    factor = stu_solution.multiply_factors([FE, FS])\n  File "../students/luxiu/A4/bnetbase.py", line 327, in multiply_factors\n    val_1 = fact_1.get_value([dom1[j]])\n  File "../students/luxiu/A4/bnetbase.py", line 226, in get_value\n    index = index * v.domain_size() + v.value_index(variable_values[0])\nIndexError: list index out of range\n'
old_multiply_factors_tests: 
OMF Test 1 ....
passed.
====================
Test Case: [function=old_restrict_factor_tests]	[0/3]
	ORF Test 2 ....
ORF Test 3 ....
old_restrict_factor_tests: 
ORF Test 1 ....
A runtime error occurred: 'Traceback (most recent call last):\n  File "/Users/JaglalLab/Desktop/A4/A4-Final/autograder/auto_grader/student_grader/assignment/A4_tests.py", line 1049, in old_restrict_factor_tests\n    value = factor.get_value_at_current_assignments()\nAttributeError: \'NoneType\' object has no attribute \'get_value_at_current_assignments\'\n'
A runtime error occurred: 'Traceback (most recent call last):\n  File "/Users/JaglalLab/Desktop/A4/A4-Final/autograder/auto_grader/student_grader/assignment/A4_tests.py", line 1030, in old_restrict_factor_tests\n    value = factor.get_value_at_current_assignments()\nAttributeError: \'NoneType\' object has no attribute \'get_value_at_current_assignments\'\n'
A runtime error occurred: 'Traceback (most recent call last):\n  File "/Users/JaglalLab/Desktop/A4/A4-Final/autograder/auto_grader/student_grader/assignment/A4_tests.py", line 1012, in old_restrict_factor_tests\n    value = factor.get_value_at_current_assignments()\nAttributeError: \'NoneType\' object has no attribute \'get_value_at_current_assignments\'\n'
====================
Test Case: [function=old_sum_out_variable_tests]	[0/2]
	A runtime error occurred: 'Traceback (most recent call last):\n  File "/Users/JaglalLab/Desktop/A4/A4-Final/autograder/auto_grader/student_grader/assignment/A4_tests.py", line 970, in old_sum_out_variable_tests\n    values = (factor.get_value(["s", "b"]), factor.get_value(["s", "-b"]), factor.get_value(["-s", "b"]), factor.get_value(["-s", "-b"]))\nAttributeError: \'NoneType\' object has no attribute \'get_value\'\n'
old_sum_out_variable_tests: 
OSOV Test 2 ....
A runtime error occurred: 'Traceback (most recent call last):\n  File "/Users/JaglalLab/Desktop/A4/A4-Final/autograder/auto_grader/student_grader/assignment/A4_tests.py", line 953, in old_sum_out_variable_tests\n    value = factor.get_value_at_current_assignments()\nAttributeError: \'NoneType\' object has no attribute \'get_value_at_current_assignments\'\n'
OSOV Test 1 ....
====================
Test Case: [function=restrict_factor_test_1]	[0/2]
	A runtime error occurred: 'Traceback (most recent call last):\n  File "/Users/JaglalLab/Desktop/A4/A4-Final/autograder/auto_grader/student_grader/assignment/A4_tests.py", line 452, in restrict_factor_test_1\n    value = factor.get_value_at_current_assignments()\nAttributeError: \'NoneType\' object has no attribute \'get_value_at_current_assignments\'\n'

Restrict Factor Tests
restrict_factor_test_1: 
RF Test 1 ....
====================
Test Case: [function=restrict_factor_test_2]	[0/2]
	A runtime error occurred: 'Traceback (most recent call last):\n  File "/Users/JaglalLab/Desktop/A4/A4-Final/autograder/auto_grader/student_grader/assignment/A4_tests.py", line 485, in restrict_factor_test_2\n    value = factor.get_value_at_current_assignments()\nAttributeError: \'NoneType\' object has no attribute \'get_value_at_current_assignments\'\n'
restrict_factor_test_2: 
RF Test 2 ....
====================
Test Case: [function=restrict_factor_test_3]	[0/2]
	restrict_factor_test_3: 
A runtime error occurred: 'Traceback (most recent call last):\n  File "/Users/JaglalLab/Desktop/A4/A4-Final/autograder/auto_grader/student_grader/assignment/A4_tests.py", line 521, in restrict_factor_test_3\n    value = factor.get_value_at_current_assignments()\nAttributeError: \'NoneType\' object has no attribute \'get_value_at_current_assignments\'\n'
RF Test 3 ....
====================
Test Case: [function=sum_out_variable_test_1]	[0/2]
	sum_out_variable_test_1: 
A runtime error occurred: 'Traceback (most recent call last):\n  File "/Users/JaglalLab/Desktop/A4/A4-Final/autograder/auto_grader/student_grader/assignment/A4_tests.py", line 552, in sum_out_variable_test_1\n    value = factor.get_value_at_current_assignments()\nAttributeError: \'NoneType\' object has no attribute \'get_value_at_current_assignments\'\n'
SOV Test 1 ....
====================
Test Case: [function=sum_out_variable_test_2]	[0/2]
	SOV Test 2 ....
sum_out_variable_test_2: 
A runtime error occurred: 'Traceback (most recent call last):\n  File "/Users/JaglalLab/Desktop/A4/A4-Final/autograder/auto_grader/student_grader/assignment/A4_tests.py", line 584, in sum_out_variable_test_2\n    values = (factor.get_value(["present"]), factor.get_value(["absent"]))\nAttributeError: \'NoneType\' object has no attribute \'get_value\'\n'
====================
Test Case: [function=sum_out_variable_test_3]	[0/2]
	sum_out_variable_test_3: 
A runtime error occurred: 'Traceback (most recent call last):\n  File "/Users/JaglalLab/Desktop/A4/A4-Final/autograder/auto_grader/student_grader/assignment/A4_tests.py", line 620, in sum_out_variable_test_3\n    values = (factor2.get_value(["true"]), factor2.get_value(["false"]))\nAttributeError: \'NoneType\' object has no attribute \'get_value\'\n'
SOV Test 3 ....
====================
Test Case: [function=ve_test_1]	[0/2]
	A runtime error occurred: 'Traceback (most recent call last):\n  File "/Users/JaglalLab/Desktop/A4/A4-Final/autograder/auto_grader/student_grader/assignment/A4_tests.py", line 85, in ve_test_1\n    if abs(probs[0] - 0.6) < 0.001 and abs(probs[1] - 0.4) < 0.001:\nTypeError: \'NoneType\' object is not subscriptable\n'
ve_test_1: 
VE Test 1 ....
====================
Test Case: [function=ve_test_2]	[0/2]
	VE Test 2 ....
ve_test_2: 
A runtime error occurred: 'Traceback (most recent call last):\n  File "/Users/JaglalLab/Desktop/A4/A4-Final/autograder/auto_grader/student_grader/assignment/A4_tests.py", line 118, in ve_test_2\n    if abs(probs[0] - 0.789) < 0.001 and probs[1] == 0.21:\nTypeError: \'NoneType\' object is not subscriptable\n'
====================
Test Case: [function=ve_test_3]	[0/2]
	A runtime error occurred: 'Traceback (most recent call last):\n  File "/Users/JaglalLab/Desktop/A4/A4-Final/autograder/auto_grader/student_grader/assignment/A4_tests.py", line 150, in ve_test_3\n    if abs(probs[0] - 0.8106077620781144) < 0.001 and abs(probs[1] - 0.1893922379218856) < 0.001:\nTypeError: \'NoneType\' object is not subscriptable\n'
ve_test_3: 
VE Test 3 ....
====================
Test Case: [function=ve_test_4]	[0/2]
	VE Test 4 ....
A runtime error occurred: 'Traceback (most recent call last):\n  File "/Users/JaglalLab/Desktop/A4/A4-Final/autograder/auto_grader/student_grader/assignment/A4_tests.py", line 184, in ve_test_4\n    if abs(probs[0] - 0.145) < 0.001 and abs(probs[1] - 0.855) < 0.001:\nTypeError: \'NoneType\' object is not subscriptable\n'
ve_test_4: 
====================
Test Case: [function=ve_test_5]	[0/2]
	ve_test_5: 
A runtime error occurred: 'Traceback (most recent call last):\n  File "/Users/JaglalLab/Desktop/A4/A4-Final/autograder/auto_grader/student_grader/assignment/A4_tests.py", line 218, in ve_test_5\n    if abs(probs[0] - 0.5760396859045477) < 0.001 and abs(probs[1] - 0.4239603140954523) < 0.001:\nTypeError: \'NoneType\' object is not subscriptable\n'
VE Test 5 ....
====================
Test Case: [function=ve_test_6]	[0/2]
	VE Test 6 ....
ve_test_6: 
A runtime error occurred: 'Traceback (most recent call last):\n  File "/Users/JaglalLab/Desktop/A4/A4-Final/autograder/auto_grader/student_grader/assignment/A4_tests.py", line 248, in ve_test_6\n    if abs(probs[0] - 0.055) < 0.001 and abs(probs[1] - 0.945) < 0.001:\nTypeError: \'NoneType\' object is not subscriptable\n'
====================
Test Case: [function=ve_test_7]	[0/2]
	A runtime error occurred: 'Traceback (most recent call last):\n  File "/Users/JaglalLab/Desktop/A4/A4-Final/autograder/auto_grader/student_grader/assignment/A4_tests.py", line 284, in ve_test_7\n    if abs(probs1[0] - 0.6339) < 0.0001 and abs(probs1[1] - 0.366) < 0.0001 and abs(probs2[0] - 0.3964) < 0.0001 and abs(probs2[1] - 0.60357) < 0.0001:\nTypeError: \'NoneType\' object is not subscriptable\n'
VE Test 7 ....
ve_test_7: 